Workbook

Sheet Summary Dashboard
A1: ADVERTISING CAMPAIGN PERFORMANCE DASHBOARD
A3: KEY METRICS SUMMARY | H3: TOP AUDIENCE SEGMENTS BY IMPRESSIONS
A4: Total Impressions | B4: =SUM(PBL_DA_CAPSTONE_DATA!K:K) -> 85705314 | H4: Audience Segment | I4: Impressions | J4: Clicks | K4: Conversions | L4: Gross Cost
A5: Total Clicks | B5: =SUM(PBL_DA_CAPSTONE_DATA!L:L) -> 233099 | H5: Automotive | I5: =SUMIF(PBL_DA_CAPSTONE_DATA!A:A,"Automotive",PBL_DA_CAPSTONE_DATA!K:K) -> 12709966 | J5: =SUMIF(PBL_DA_CAPSTONE_DATA!A:A,"Automotive",PBL_DA_CAPSTONE_DATA!L:L) -> 37608 | K5: =SUMIF(PBL_DA_CAPSTONE_DATA!A:A,"Automotive",PBL_DA_CAPSTONE_DATA!U:U) -> 0 | L5: =SUMIF(PBL_DA_CAPSTONE_DATA!A:A,"Automotive",PBL_DA_CAPSTONE_DATA!V:V) -> 0
A6: Total Viewable Impressions | B6: =SUM(PBL_DA_CAPSTONE_DATA!M:M) -> 41896691 | H6: Beauty and Fitness | I6: =SUMIF(PBL_DA_CAPSTONE_DATA!A:A,"Beauty and Fitness",PBL_DA_CAPSTONE_DATA!K:K) -> 4609241 | J6: =SUMIF(PBL_DA_CAPSTONE_DATA!A:A,"Beauty and Fitness",PBL_DA_CAPSTONE_DATA!L:L) -> 14384 | K6: =SUMIF(PBL_DA_CAPSTONE_DATA!A:A,"Beauty and Fitness",PBL_DA_CAPSTONE_DATA!U:U) -> 0 | L6: =SUMIF(PBL_DA_CAPSTONE_DATA!A:A,"Beauty and Fitness",PBL_DA_CAPSTONE_DATA!V:V) -> 0
A7: Total Conversions | B7: =SUM(PBL_DA_CAPSTONE_DATA!U:U) -> 0 | H7: B2B | I7: =SUMIF(PBL_DA_CAPSTONE_DATA!A:A,"B2B",PBL_DA_CAPSTONE_DATA!K:K) -> 2617549 | J7: =SUMIF(PBL_DA_CAPSTONE_DATA!A:A,"B2B",PBL_DA_CAPSTONE_DATA!L:L) -> 7372 | K7: =SUMIF(PBL_DA_CAPSTONE_DATA!A:A,"B2B",PBL_DA_CAPSTONE_DATA!U:U) -> 0 | L7: =SUMIF(PBL_DA_CAPSTONE_DATA!A:A,"B2B",PBL_DA_CAPSTONE_DATA!V:V) -> 0
A8: Total Gross Cost | B8: =SUM(PBL_DA_CAPSTONE_DATA!V:V) -> 0 | H8: Brand Propensities | I8: =SUMIF(PBL_DA_CAPSTONE_DATA!A:A,"Brand Propensities",PBL_DA_CAPSTONE_DATA!K:K) -> 4191580 | J8: =SUMIF(PBL_DA_CAPSTONE_DATA!A:A,"Brand Propensities",PBL_DA_CAPSTONE_DATA!L:L) -> 11567 | K8: =SUMIF(PBL_DA_CAPSTONE_DATA!A:A,"Brand Propensities",PBL_DA_CAPSTONE_DATA!U:U) -> 0 | L8: =SUMIF(PBL_DA_CAPSTONE_DATA!A:A,"Brand Propensities",PBL_DA_CAPSTONE_DATA!V:V) -> 0
A9: Overall CTR (Click-Through Rate) | B9: =IF(B4>0,B5/B4,0) -> 0.002719773 | H9: Arts and Entertainment | I9: =SUMIF(PBL_DA_CAPSTONE_DATA!A:A,"Arts and Entertainment",PBL_DA_CAPSTONE_DATA!K:K) -> 1279283 | J9: =SUMIF(PBL_DA_CAPSTONE_DATA!A:A,"Arts and Entertainment",PBL_DA_CAPSTONE_DATA!L:L) -> 2947 | K9: =SUMIF(PBL_DA_CAPSTONE_DATA!A:A,"Arts and Entertainment",PBL_DA_CAPSTONE_DATA!U:U) -> 0 | L9: =SUMIF(PBL_DA_CAPSTONE_DATA!A:A,"Arts and Entertainment",PBL_DA_CAPSTONE_DATA!V:V) -> 0
H10: Finance | I10: =SUMIF(PBL_DA_CAPSTONE_DATA!A:A,"Finance",PBL_DA_CAPSTONE_DATA!K:K) -> 13200810 | J10: =SUMIF(PBL_DA_CAPSTONE_DATA!A:A,"Finance",PBL_DA_CAPSTONE_DATA!L:L) -> 25675 | K10: =SUMIF(PBL_DA_CAPSTONE_DATA!A:A,"Finance",PBL_DA_CAPSTONE_DATA!U:U) -> 0 | L10: =SUMIF(PBL_DA_CAPSTONE_DATA!A:A,"Finance",PBL_DA_CAPSTONE_DATA!V:V) -> 0
A11: PERFORMANCE BY STATE | H11: Demographics | I11: =SUMIF(PBL_DA_CAPSTONE_DATA!A:A,"Demographics",PBL_DA_CAPSTONE_DATA!K:K) -> 886174 | J11: =SUMIF(PBL_DA_CAPSTONE_DATA!A:A,"Demographics",PBL_DA_CAPSTONE_DATA!L:L) -> 1981 | K11: =SUMIF(PBL_DA_CAPSTONE_DATA!A:A,"Demographics",PBL_DA_CAPSTONE_DATA!U:U) -> 0 | L11: =SUMIF(PBL_DA_CAPSTONE_DATA!A:A,"Demographics",PBL_DA_CAPSTONE_DATA!V:V) -> 0
A12: State | B12: Impressions | C12: Clicks | D12: Conversions | E12: Gross Cost | F12: CTR | H12: Food | I12: =SUMIF(PBL_DA_CAPSTONE_DATA!A:A,"Food",PBL_DA_CAPSTONE_DATA!K:K) -> 1981212 | J12: =SUMIF(PBL_DA_CAPSTONE_DATA!A:A,"Food",PBL_DA_CAPSTONE_DATA!L:L) -> 5498 | K12: =SUMIF(PBL_DA_CAPSTONE_DATA!A:A,"Food",PBL_DA_CAPSTONE_DATA!U:U) -> 0 | L12: =SUMIF(PBL_DA_CAPSTONE_DATA!A:A,"Food",PBL_DA_CAPSTONE_DATA!V:V) -> 0
A13: California | B13: =SUMIF(PBL_DA_CAPSTONE_DATA!G:G,"*California*",PBL_DA_CAPSTONE_DATA!K:K) -> 20155086 | C13: =SUMIF(PBL_DA_CAPSTONE_DATA!G:G,"*California*",PBL_DA_CAPSTONE_DATA!L:L) -> 55756 | D13: =SUMIF(PBL_DA_CAPSTONE_DATA!G:G,"*California*",PBL_DA_CAPSTONE_DATA!U:U) -> 0 | E13: =SUMIF(PBL_DA_CAPSTONE_DATA!G:G,"*California*",PBL_DA_CAPSTONE_DATA!V:V) -> 0 | F13: =IF(B13>0,C13/B13,0) -> 0.0027663489 | H13: Home and Garden | I13: =SUMIF(PBL_DA_CAPSTONE_DATA!A:A,"Home and Garden",PBL_DA_CAPSTONE_DATA!K:K) -> 281692 | J13: =SUMIF(PBL_DA_CAPSTONE_DATA!A:A,"Home and Garden",PBL_DA_CAPSTONE_DATA!L:L) -> 1059 | K13: =SUMIF(PBL_DA_CAPSTONE_DATA!A:A,"Home and Garden",PBL_DA_CAPSTONE_DATA!U:U) -> 0 | L13: =SUMIF(PBL_DA_CAPSTONE_DATA!A:A,"Home and Garden",PBL_DA_CAPSTONE_DATA!V:V) -> 0
A14: Florida | B14: =SUMIF(PBL_DA_CAPSTONE_DATA!G:G,"*Florida*",PBL_DA_CAPSTONE_DATA!K:K) -> 12361492 | C14: =SUMIF(PBL_DA_CAPSTONE_DATA!G:G,"*Florida*",PBL_DA_CAPSTONE_DATA!L:L) -> 36764 | D14: =SUMIF(PBL_DA_CAPSTONE_DATA!G:G,"*Florida*",PBL_DA_CAPSTONE_DATA!U:U) -> 0 | E14: =SUMIF(PBL_DA_CAPSTONE_DATA!G:G,"*Florida*",PBL_DA_CAPSTONE_DATA!V:V) -> 0 | F14: =IF(B14>0,C14/B14,0) -> 0.0029740747 | H14: Media and Entertainment | I14: =SUMIF(PBL_DA_CAPSTONE_DATA!A:A,"Media and Entertainment",PBL_DA_CAPSTONE_DATA!K:K) -> 2705224 | J14: =SUMIF(PBL_DA_CAPSTONE_DATA!A:A,"Media and Entertainment",PBL_DA_CAPSTONE_DATA!L:L) -> 8163 | K14: =SUMIF(PBL_DA_CAPSTONE_DATA!A:A,"Media and Entertainment",PBL_DA_CAPSTONE_DATA!U:U) -> 0 | L14: =SUMIF(PBL_DA_CAPSTONE_DATA!A:A,"Media and Entertainment",PBL_DA_CAPSTONE_DATA!V:V) -> 0
A15: Illinois | B15: =SUMIF(PBL_DA_CAPSTONE_DATA!G:G,"*Illinois*",PBL_DA_CAPSTONE_DATA!K:K) -> 27857546 | C15: =SUMIF(PBL_DA_CAPSTONE_DATA!G:G,"*Illinois*",PBL_DA_CAPSTONE_DATA!L:L) -> 69176 | D15: =SUMIF(PBL_DA_CAPSTONE_DATA!G:G,"*Illinois*",PBL_DA_CAPSTONE_DATA!U:U) -> 0 | E15: =SUMIF(PBL_DA_CAPSTONE_DATA!G:G,"*Illinois*",PBL_DA_CAPSTONE_DATA!V:V) -> 0 | F15: =IF(B15>0,C15/B15,0) -> 0.0024832051
A16: New York | B16: =SUMIF(PBL_DA_CAPSTONE_DATA!G:G,"*New York*",PBL_DA_CAPSTONE_DATA!K:K) -> 12389658 | C16: =SUMIF(PBL_DA_CAPSTONE_DATA!G:G,"*New York*",PBL_DA_CAPSTONE_DATA!L:L) -> 35141 | D16: =SUMIF(PBL_DA_CAPSTONE_DATA!G:G,"*New York*",PBL_DA_CAPSTONE_DATA!U:U) -> 0 | E16: =SUMIF(PBL_DA_CAPSTONE_DATA!G:G,"*New York*",PBL_DA_CAPSTONE_DATA!V:V) -> 0 | F16: =IF(B16>0,C16/B16,0) -> 0.0028363172
A17: Tennessee | B17: =SUMIF(PBL_DA_CAPSTONE_DATA!G:G,"*Tennessee*",PBL_DA_CAPSTONE_DATA!K:K) -> 6235010 | C17: =SUMIF(PBL_DA_CAPSTONE_DATA!G:G,"*Tennessee*",PBL_DA_CAPSTONE_DATA!L:L) -> 17186 | D17: =SUMIF(PBL_DA_CAPSTONE_DATA!G:G,"*Tennessee*",PBL_DA_CAPSTONE_DATA!U:U) -> 0 | E17: =SUMIF(PBL_DA_CAPSTONE_DATA!G:G,"*Tennessee*",PBL_DA_CAPSTONE_DATA!V:V) -> 0 | F17: =IF(B17>0,C17/B17,0) -> 0.0027563709 | H17: TOP AD EXCHANGES
A18: Michigan | B18: =SUMIF(PBL_DA_CAPSTONE_DATA!G:G,"*Michigan*",PBL_DA_CAPSTONE_DATA!K:K) -> 2424081 | C18: =SUMIF(PBL_DA_CAPSTONE_DATA!G:G,"*Michigan*",PBL_DA_CAPSTONE_DATA!L:L) -> 7456 | D18: =SUMIF(PBL_DA_CAPSTONE_DATA!G:G,"*Michigan*",PBL_DA_CAPSTONE_DATA!U:U) -> 0 | E18: =SUMIF(PBL_DA_CAPSTONE_DATA!G:G,"*Michigan*",PBL_DA_CAPSTONE_DATA!V:V) -> 0 | F18: =IF(B18>0,C18/B18,0) -> 0.0030758048 | H18: Exchange | I18: Impressions | J18: Clicks | K18: Gross Cost
A19: Indiana | B19: =SUMIF(PBL_DA_CAPSTONE_DATA!G:G,"*Indiana*",PBL_DA_CAPSTONE_DATA!K:K) -> 1901207 | C19: =SUMIF(PBL_DA_CAPSTONE_DATA!G:G,"*Indiana*",PBL_DA_CAPSTONE_DATA!L:L) -> 4811 | D19: =SUMIF(PBL_DA_CAPSTONE_DATA!G:G,"*Indiana*",PBL_DA_CAPSTONE_DATA!U:U) -> 0 | E19: =SUMIF(PBL_DA_CAPSTONE_DATA!G:G,"*Indiana*",PBL_DA_CAPSTONE_DATA!V:V) -> 0 | F19: =IF(B19>0,C19/B19,0) -> 0.0025304977 | H19: Google Ad Manager | I19: =SUMIF(PBL_DA_CAPSTONE_DATA!I:I,"Google Ad Manager",PBL_DA_CAPSTONE_DATA!K:K) -> 34342307 | J19: =SUMIF(PBL_DA_CAPSTONE_DATA!I:I,"Google Ad Manager",PBL_DA_CAPSTONE_DATA!L:L) -> 97488 | K19: =SUMIF(PBL_DA_CAPSTONE_DATA!I:I,"Google Ad Manager",PBL_DA_CAPSTONE_DATA!V:V) -> 0
A20: Georgia | B20: =SUMIF(PBL_DA_CAPSTONE_DATA!G:G,"*Georgia*",PBL_DA_CAPSTONE_DATA!K:K) -> 724339 | C20: =SUMIF(PBL_DA_CAPSTONE_DATA!G:G,"*Georgia*",PBL_DA_CAPSTONE_DATA!L:L) -> 2045 | D20: =SUMIF(PBL_DA_CAPSTONE_DATA!G:G,"*Georgia*",PBL_DA_CAPSTONE_DATA!U:U) -> 0 | E20: =SUMIF(PBL_DA_CAPSTONE_DATA!G:G,"*Georgia*",PBL_DA_CAPSTONE_DATA!V:V) -> 0 | F20: =IF(B20>0,C20/B20,0) -> 0.0028232637 | H20: BidSwitch | I20: =SUMIF(PBL_DA_CAPSTONE_DATA!I:I,"BidSwitch",PBL_DA_CAPSTONE_DATA!K:K) -> 8708607 | J20: =SUMIF(PBL_DA_CAPSTONE_DATA!I:I,"BidSwitch",PBL_DA_CAPSTONE_DATA!L:L) -> 23187 | K20: =SUMIF(PBL_DA_CAPSTONE_DATA!I:I,"BidSwitch",PBL_DA_CAPSTONE_DATA!V:V) -> 0
A21: Alabama | B21: =SUMIF(PBL_DA_CAPSTONE_DATA!G:G,"*Alabama*",PBL_DA_CAPSTONE_DATA!K:K) -> 183819 | C21: =SUMIF(PBL_DA_CAPSTONE_DATA!G:G,"*Alabama*",PBL_DA_CAPSTONE_DATA!L:L) -> 693 | D21: =SUMIF(PBL_DA_CAPSTONE_DATA!G:G,"*Alabama*",PBL_DA_CAPSTONE_DATA!U:U) -> 0 | E21: =SUMIF(PBL_DA_CAPSTONE_DATA!G:G,"*Alabama*",PBL_DA_CAPSTONE_DATA!V:V) -> 0 | F21: =IF(B21>0,C21/B21,0) -> 0.0037700129 | H21: PubMatic | I21: =SUMIF(PBL_DA_CAPSTONE_DATA!I:I,"PubMatic",PBL_DA_CAPSTONE_DATA!K:K) -> 13445406 | J21: =SUMIF(PBL_DA_CAPSTONE_DATA!I:I,"PubMatic",PBL_DA_CAPSTONE_DATA!L:L) -> 28722 | K21: =SUMIF(PBL_DA_CAPSTONE_DATA!I:I,"PubMatic",PBL_DA_CAPSTONE_DATA!V:V) -> 0
A22: Ohio | B22: =SUMIF(PBL_DA_CAPSTONE_DATA!G:G,"*Ohio*",PBL_DA_CAPSTONE_DATA!K:K) -> 256526 | C22: =SUMIF(PBL_DA_CAPSTONE_DATA!G:G,"*Ohio*",PBL_DA_CAPSTONE_DATA!L:L) -> 707 | D22: =SUMIF(PBL_DA_CAPSTONE_DATA!G:G,"*Ohio*",PBL_DA_CAPSTONE_DATA!U:U) -> 0 | E22: =SUMIF(PBL_DA_CAPSTONE_DATA!G:G,"*Ohio*",PBL_DA_CAPSTONE_DATA!V:V) -> 0 | F22: =IF(B22>0,C22/B22,0) -> 0.0027560559 | H22: Magnite DV+ | I22: =SUMIF(PBL_DA_CAPSTONE_DATA!I:I,"Magnite DV+",PBL_DA_CAPSTONE_DATA!K:K) -> 8362480 | J22: =SUMIF(PBL_DA_CAPSTONE_DATA!I:I,"Magnite DV+",PBL_DA_CAPSTONE_DATA!L:L) -> 24491 | K22: =SUMIF(PBL_DA_CAPSTONE_DATA!I:I,"Magnite DV+",PBL_DA_CAPSTONE_DATA!V:V) -> 0
H23: Index Exchange | I23: =SUMIF(PBL_DA_CAPSTONE_DATA!I:I,"Index Exchange",PBL_DA_CAPSTONE_DATA!K:K) -> 3682064 | J23: =SUMIF(PBL_DA_CAPSTONE_DATA!I:I,"Index Exchange",PBL_DA_CAPSTONE_DATA!L:L) -> 10517 | K23: =SUMIF(PBL_DA_CAPSTONE_DATA!I:I,"Index Exchange",PBL_DA_CAPSTONE_DATA!V:V) -> 0
H24: OpenX | I24: =SUMIF(PBL_DA_CAPSTONE_DATA!I:I,"OpenX",PBL_DA_CAPSTONE_DATA!K:K) -> 4462460 | J24: =SUMIF(PBL_DA_CAPSTONE_DATA!I:I,"OpenX",PBL_DA_CAPSTONE_DATA!L:L) -> 13209 | K24: =SUMIF(PBL_DA_CAPSTONE_DATA!I:I,"OpenX",PBL_DA_CAPSTONE_DATA!V:V) -> 0
A25: PERFORMANCE BY DEVICE
A26: Device Make | B26: Impressions | C26: Clicks | D26: Gross Cost | E26: CTR
A27: Smartphone | B27: =SUMIF(PBL_DA_CAPSTONE_DATA!J:J,"Smartphone",PBL_DA_CAPSTONE_DATA!K:K) -> 78213490 | C27: =SUMIF(PBL_DA_CAPSTONE_DATA!J:J,"Smartphone",PBL_DA_CAPSTONE_DATA!L:L) -> 210740 | D27: =SUMIF(PBL_DA_CAPSTONE_DATA!J:J,"Smartphone",PBL_DA_CAPSTONE_DATA!V:V) -> 0 | E27: =IF(B27>0,C27/B27,0) -> 0.0026944201
A28: Windows PC | B28: =SUMIF(PBL_DA_CAPSTONE_DATA!J:J,"Windows PC",PBL_DA_CAPSTONE_DATA!K:K) -> 4686681 | C28: =SUMIF(PBL_DA_CAPSTONE_DATA!J:J,"Windows PC",PBL_DA_CAPSTONE_DATA!L:L) -> 13372 | D28: =SUMIF(PBL_DA_CAPSTONE_DATA!J:J,"Windows PC",PBL_DA_CAPSTONE_DATA!V:V) -> 0 | E28: =IF(B28>0,C28/B28,0) -> 0.0028531918
A29: Apple PC | B29: =SUMIF(PBL_DA_CAPSTONE_DATA!J:J,"Apple PC",PBL_DA_CAPSTONE_DATA!K:K) -> 2805143 | C29: =SUMIF(PBL_DA_CAPSTONE_DATA!J:J,"Apple PC",PBL_DA_CAPSTONE_DATA!L:L) -> 8987 | D29: =SUMIF(PBL_DA_CAPSTONE_DATA!J:J,"Apple PC",PBL_DA_CAPSTONE_DATA!V:V) -> 0 | E29: =IF(B29>0,C29/B29,0) -> 0.0032037582
A74: PERFORMANCE BY CREATIVE SIZE | H74: PERFORMANCE BY CREATIVE MESSAGING
A75: Creative Size | B75: Impressions | C75: Clicks | D75: Conversions | E75: CTR | H75: Creative Messaging | I75: Impressions | J75: Clicks | K75: Conversions | L75: CTR
A76: 320x50 | B76: =SUMIF(PBL_DA_CAPSTONE_DATA!D:D,"320x50",PBL_DA_CAPSTONE_DATA!K:K) -> 40014637 | C76: =SUMIF(PBL_DA_CAPSTONE_DATA!D:D,"320x50",PBL_DA_CAPSTONE_DATA!L:L) -> 102729 | D76: =SUMIF(PBL_DA_CAPSTONE_DATA!D:D,"320x50",PBL_DA_CAPSTONE_DATA!U:U) -> 0 | E76: =IF(B76>0,C76/B76,0) -> 0.0025672856 | H76: Subscribe Today - 10% Discount | I76: =SUMIF(PBL_DA_CAPSTONE_DATA!E:E,"Subscribe Today - 10% Discount",PBL_DA_CAPSTONE_DATA!K:K) -> 22412582 | J76: =SUMIF(PBL_DA_CAPSTONE_DATA!E:E,"Subscribe Today - 10% Discount",PBL_DA_CAPSTONE_DATA!L:L) -> 65302 | K76: =SUMIF(PBL_DA_CAPSTONE_DATA!E:E,"Subscribe Today - 10% Discount",PBL_DA_CAPSTONE_DATA!U:U) -> 0 | L76: =IF(I76>0,J76/I76,0) -> 0.0029136313
A77: 300x250 | B77: =SUMIF(PBL_DA_CAPSTONE_DATA!D:D,"300x250",PBL_DA_CAPSTONE_DATA!K:K) -> 40755215 | C77: =SUMIF(PBL_DA_CAPSTONE_DATA!D:D,"300x250",PBL_DA_CAPSTONE_DATA!L:L) -> 115476 | D77: =SUMIF(PBL_DA_CAPSTONE_DATA!D:D,"300x250",PBL_DA_CAPSTONE_DATA!U:U) -> 0 | E77: =IF(B77>0,C77/B77,0) -> 0.0028334043 | H77: Sign up Today - 10% Off | I77: =SUMIF(PBL_DA_CAPSTONE_DATA!E:E,"Sign up Today - 10% Off",PBL_DA_CAPSTONE_DATA!K:K) -> 21106602 | J77: =SUMIF(PBL_DA_CAPSTONE_DATA!E:E,"Sign up Today - 10% Off",PBL_DA_CAPSTONE_DATA!L:L) -> 60421 | K77: =SUMIF(PBL_DA_CAPSTONE_DATA!E:E,"Sign up Today - 10% Off",PBL_DA_CAPSTONE_DATA!U:U) -> 0 | L77: =IF(I77>0,J77/I77,0) -> 0.0028626588
A78: 300x50 | B78: =SUMIF(PBL_DA_CAPSTONE_DATA!D:D,"300x50",PBL_DA_CAPSTONE_DATA!K:K) -> 4935462 | C78: =SUMIF(PBL_DA_CAPSTONE_DATA!D:D,"300x50",PBL_DA_CAPSTONE_DATA!L:L) -> 14894 | D78: =SUMIF(PBL_DA_CAPSTONE_DATA!D:D,"300x50",PBL_DA_CAPSTONE_DATA!U:U) -> 0 | E78: =IF(B78>0,C78/B78,0) -> 0.0030177519 | H78: Sign up Now - 10% Off | I78: =SUMIF(PBL_DA_CAPSTONE_DATA!E:E,"Sign up Now - 10% Off",PBL_DA_CAPSTONE_DATA!K:K) -> 17150590 | J78: =SUMIF(PBL_DA_CAPSTONE_DATA!E:E,"Sign up Now - 10% Off",PBL_DA_CAPSTONE_DATA!L:L) -> 48516 | K78: =SUMIF(PBL_DA_CAPSTONE_DATA!E:E,"Sign up Now - 10% Off",PBL_DA_CAPSTONE_DATA!U:U) -> 0 | L78: =IF(I78>0,J78/I78,0) -> 0.002828824
H79: 10% Discount - Ends 6/1 | I79: =SUMIF(PBL_DA_CAPSTONE_DATA!E:E,"10% Discount - Ends 6/1",PBL_DA_CAPSTONE_DATA!K:K) -> 25035540 | J79: =SUMIF(PBL_DA_CAPSTONE_DATA!E:E,"10% Discount - Ends 6/1",PBL_DA_CAPSTONE_DATA!L:L) -> 58860 | K79: =SUMIF(PBL_DA_CAPSTONE_DATA!E:E,"10% Discount - Ends 6/1",PBL_DA_CAPSTONE_DATA!U:U) -> 0 | L79: =IF(I79>0,J79/I79,0) -> 0.0023510577
A81: KEY INSIGHTS
A82: 1. Illinois leads in total impressions with the highest volume of ad delivery
A83: 2. Smartphones dominate device distribution, accounting for ~91% of all impressions
A84: 3. Google Ad Manager is the primary ad exchange for campaign delivery (highest viewable and measurable impressions)
A85: 4. Alabama has the highest CTR (0.38%) indicating strong engagement in that state
A86: 5. Apple PC users show the highest CTR among devices (0.32%)
...

Sheet Pivot Table
B3: CTR | C3: CVR | D3: Viewable Rate | E3: vCPM | F3: CPM | G3: CPC | H3: CPA
A4: Arts and Entertainment
A5: California | B5: 0.0022130112 | C5: 0.020818876 | D5: 0.61139693 | E5: 42.272938 | F5: 23.963141 | G5: 10.828297 | H5: 520.11918
A6: Florida | B6: 0.0039358661 | C6: 0.22105263 | D6: 0.5717074 | E6: 1120.5845 | F6: 598.33834 | G6: 152.02203 | H6: 687.71869
A7: Illinois | B7: 0.0021484172 | C7: 0.057578323 | D7: 0.56607252 | E7: 72.340125 | F7: 34.788748 | G7: 16.192734 | H7: 281.22968
A8: New York | B8: 0.0028682059 | C8: 0.2 | D8: 0.3561147 | E8: 1565.9563 | F8: 352.80615 | G8: 123.00587 | H8: 615.02932
A9: Tennessee | B9: 0.0047094983 | C9: 0.078947368 | D9: 0.37618609 | E9: 1202.6326 | F9: 413.63597 | G9: 87.830156 | H9: 1112.5153
A10: Arts and Entertainment Total | B10: 0.0023036341 | C10: 0.048184595 | D10: 0.58243267 | E10: 106.69219 | F10: 55.325718 | G10: 24.016712 | H10: 498.43134
A11: Automotive
A12: Alabama | B12: 0.0062030464 | C12: 0.088888889 | D12: 0.065269822 | E12: 6375.507 | F12: 380.53547 | G12: 61.346546 | H12: 690.14864
A13: Arkansas | B13: 0.0032192295 | C13: 0.4 | D13: 0.7133149 | E13: 741.90279 | F13: 493.03616 | G13: 153.15347 | H13: 382.88367
A14: California | B14: 0.0029200681 | C14: 0.028247096 | D14: 0.6980998 | E14: 74.064588 | F14: 46.035826 | G14: 15.765326 | H14: 558.12201
A15: Florida | B15: 0.0032648215 | C15: 0.044713439 | D15: 0.5015546 | E15: 227.70621 | F15: 100.2227 | G15: 30.697756 | H15: 686.5443
A16: Georgia | B16: 0.0037758875 | C16: 0.0368 | D16: 0.39808108 | E16: 238.53388 | F16: 78.804201 | G16: 20.870378 | H16: 567.12985
A17: Illinois | B17: 0.0028513436 | C17: 0.02393617 | D17: 0.70811554 | E17: 48.329426 | F17: 28.493048 | G17: 9.9928497 | H17: 417.47905
A18: Indiana | B18: 0.0029766919 | C18: 0.13207547 | D18: 0.57038056 | E18: 599.3288 | F18: 314.05435 | G18: 105.50448 | H18: 798.81967
A19: Michigan | B19: 0.0035694851 | C19: 0.12403101 | D19: 0.528463 | E19: 410.10865 | F19: 185.40925 | G19: 51.942856 | H19: 418.78928
A20: Mississippi | B20: 0.0024703176 | C20: 0.06875 | D20: 0.52530197 | E20: 405.9304 | F20: 56.829253 | G20: 23.004837 | H20: 334.61581
A21: New York | B21: 0.0030898884 | C21: 0.039371119 | D21: 0.52155132 | E21: 100.49153 | F21: 45.228478 | G21: 14.637576 | H21: 371.78462
A22: Tennessee | B22: 0.0026981638 | C22: 0.035033087 | D22: 0.5659583 | E22: 107.3297 | F22: 52.020684 | G22: 19.280032 | H22: 550.3378
A23: Automotive Total | B23: 0.0029589379 | C23: 0.033290789 | D23: 0.63077418 | E23: 89.184785 | F23: 47.884422 | G23: 16.182976 | H23: 486.10972
A24: B2B
A25: California | B25: 0.0027208184 | C25: 0.019972261 | D25: 0.33851883 | E25: 68.434449 | F25: 20.879297 | G25: 7.6739031 | H25: 384.22807
A26: Florida | B26: 0.0027392541 | C26: 0.062116564 | D26: 0.51911895 | E26: 116.67639 | F26: 53.086016 | G26: 19.379734 | H26: 311.9898
A27: Illinois | B27: 0.0026775113 | C27: 0.078023407 | D27: 0.4655921 | E27: 211.66947 | F27: 90.731174 | G27: 33.886383 | H27: 434.31047
A28: Indiana | B28: 0.0028874369 | C28: 0.061326658 | D28: 0.44984559 | E28: 19.80629 | F28: 8.2260422 | G28: 2.848908 | H28: 46.454643
A29: Michigan | B29: 0.0020970503 | C29: 0.11764706 | D29: 0.49301763 | E29: 126.52742 | F29: 55.65388 | G29: 26.539126 | H29: 225.58257
A30: New York | B30: 0.009427494 | C30: 0.045454545 | D30: 0.7139613 | E30: 337.65669 | F30: 227.45814 | G30: 24.127105 | H30: 530.79632
A31: Tennessee | B31: 0.0036855316 | C31: 0.013867488 | D31: 0.48405 | E31: 101.27766 | F31: 44.342263 | G31: 12.031443 | H31: 867.60071
A32: B2B Total | B32: 0.0028163752 | C32: 0.039609333 | D32: 0.41211534 | E32: 98.052276 | F32: 36.424231 | G32: 12.933018 | H32: 326.51442
A33: Beauty and Fitness
A34: California | B34: 0.0028059154 | C34: 0.017564403 | D34: 0.6682192 | E34: 40.048641 | F34: 22.276322 | G34: 7.9390569 | H34: 451.99697
A35: Florida | B35: 0.002748094 | C35: 0.18857143 | D35: 0.63126171 | E35: 341.25249 | F35: 200.36101 | G35: 72.909082 | H35: 386.63907
A36: Illinois | B36: 0.0033085559 | C36: 0.017251816 | D36: 0.58210531 | E36: 31.190486 | F36: 16.263541 | G36: 4.9156011 | H36: 284.93239
A37: New York | B37: 0.0025946245 | C37: 0.059561129 | D37: 0.30690752 | E37: 326.08003 | F37: 89.199152 | G37: 34.378444 | H37: 577.19598
A38: Tennessee | B38: 0.0029969149 | C38: 0.27941176 | D38: 0.51229056 | E38: 706.09934 | F38: 317.79138 | G38: 106.03951 | H38: 379.50982
A39: Beauty and Fitness Total | B39: 0.0031206873 | C39: 0.024610679 | D39: 0.58984594 | E39: 54.569428 | F39: 28.313896 | G39: 9.0729678 | H39: 368.6598
A40: Brand Propensities
A41: Alabama | B41: 0.007650356 | C41: 0.02970297 | D41: 0.84369422 | E41: 156.29296 | F41: 128.69723 | G41: 16.822384 | H41: 566.3536
A42: California | B42: 0.0026923447 | C42: 0.0071455434 | D42: 0.6819242 | E42: 11.421811 | F42: 6.9211701 | G42: 2.570685 | H42: 359.7606
...

Sheet Sheet2
A3: Row Labels | B3: CPM | C3: vCPM | D3: CPA | E3: CVR | F3: CTR | G3: CPC | H3: Viewable Rate | I3: Total Viewable Imp. | J3: Total Measurable Imp. | L3: Top 5 CPA
A4: Kargo | L4: Kargo
A5: mlb.com | B5: 127.86021 | C5: 218.51995 | D5: 113.78646 | E5: 0.16666667 | F5: 0.0067421141 | G5: 18.96441 | H5: 0.6214304 | I5: 7290 | J5: 11731 | L5: Xandr - Monetize SSP (AppNexus)
A6: Xandr - Monetize SSP (AppNexus) | L6: Sovrn
A7: mail.yahoo.com | B7: 6.1861863 | C7: 11.093801 | D7: 66.561907 | E7: 0.03602812 | F7: 0.0025796195 | G7: 2.3981003 | H7: 0.62655207 | I7: 737990 | J7: 1177859 | L7: Taboola
A8: ebay.com | B8: 12.526347 | C8: 20.783073 | D8: 91.405555 | E8: 0.05760709 | F8: 0.0023788984 | G8: 5.2656081 | H8: 0.63394766 | I8: 343050 | J8: 541133 | L8: TripleLift
A9: yahoo.com | B9: 16.223486 | C9: 44.254281 | D9: 604.0193 | E9: 0.0096385542 | F9: 0.0027866438 | G9: 5.8218728 | H9: 0.43779469 | I9: 163786 | J9: 374116 | L9: PulsePoint
A10: outlook.live.com | B10: 42.915842 | C10: 50.647106 | D10: 231.27852 | E10: 0.051051051 | F10: 0.003634776 | G10: 11.807012 | H10: 0.91553988 | I10: 155260 | J10: 169583
A11: msn.com | B11: 9.6653498 | C11: 16.340343 | D11: 207.29155 | E11: 0.016032064 | F11: 0.0029083491 | G11: 3.3233114 | H11: 0.74603046 | I11: 101487 | J11: 136036
A12: nypost.com | B12: 43.421988 | C12: 80.056046 | D12: 234.41026 | E12: 0.073863636 | F12: 0.0025078549 | G12: 17.314394 | H12: 0.56992918 | I12: 76130 | J12: 133578
A13: baseball-reference.com | B13: 21.284 | C13: 153.17011 | D13: 501.0807 | E13: 0.013368984 | F13: 0.0031772192 | G13: 6.6989398 | H13: 0.16320768 | I13: 16357 | J13: 100222
A14: pandora.com | B14: 89.738254 | C14: 120.48546 | D14: 276.19073 | E14: 0.14074074 | F14: 0.0023086 | G14: 38.871288 | H14: 0.77007674 | I14: 43554 | J14: 56558
A15: dailyhodl.com | B15: 92.354833 | C15: 115.63744 | D15: 3621.4177 | E15: 0.0038461538 | F15: 0.0066306233 | G15: 13.92853 | H15: 0.83157196 | I15: 31317 | J15: 37660
A16: moneyppl.com | B16: 40.133674 | C16: 160.93404 | D16: 123.99968 | E16: 0.10619469 | F16: 0.0030477937 | G16: 13.168107 | H16: 0.40974961 | I16: 9246 | J16: 22565
A17: ajc.com | B17: 274.72416 | C17: 565.0699 | D17: 489.9156 | E17: 0.16393443 | F17: 0.0034206247 | G17: 80.314033 | H17: 0.51389959 | I17: 8670 | J17: 16871
A18: dotesports.com | B18: 224.78963 | C18: 381.53689 | D18: 270.07725 | E18: 0.5 | F18: 0.0016646321 | G18: 135.03862 | H18: 0.63798594 | I18: 10618 | J18: 16643
A19: washingtonpost.com | B19: 693.17615 | C19: 996.0054 | D19: 569.96409 | E19: 0.4 | F19: 0.0030404378 | G19: 227.98564 | H19: 0.73467423 | I19: 6867 | J19: 9347
A20: ew.com | B20: 146.48331 | C20: 216.81802 | D20: 145.31144 | E20: 0.5 | F20: 0.002016129 | G20: 72.65572 | H20: 0.73680739 | I20: 6702 | J20: 9096
A21: accuweather.com | B21: 594.65936 | C21: 1513.4556 | D21: 780.56474 | E21: 0.088888889 | F21: 0.0085706123 | G21: 69.383532 | H21: 0.53906454 | I21: 4126 | J21: 7654
... A23: fandom.com | B23: 407.2384 | C23: 2886.2454 | D23: 887.3143 | E23: 0.12727273 | F23: 0.0036060844 | G23: 112.93091 | H23: 0.61803561 | I23: 2152 | J23: 3482
A24: Sovrn
A25: realtor.com | B25: 23.446438 | C25: 43.946495 | D25: 535.83082 | E25: 0.045454545 | F25: 0.00096265764 | G25: 24.355946 | H25: 0.56291262 | I25: 60964 | J25: 108301
A26: cars.com | B26: 28.411304 | C26: 48.229503 | D26: 315.14765 | E26: 0.035502959 | F26: 0.0025392914 | G26: 11.188674 | H26: 0.63124507 | I26: 39206 | J26: 62109
A27: finance.yahoo.com | B27: 43.39611 | C27: 89.803494 | D27: 553.90795 | E27: 0.033333333 | F27: 0.0023503604 | G27: 18.463598 | H27: 0.541492 | I27: 24672 | J27: 45563
A28: screenrant.com | B28: 43.602896 | C28: 72.962291 | D28: 63.665679 | E28: 0.17142857 | F28: 0.0039950917 | G28: 10.914116 | H28: 0.62552645 | I28: 20942 | J28: 33479
A29: m.timesofindia.com | B29: 114.79664 | C29: 242.68586 | D29: 912.86285 | E29: 0.010526316 | F29: 0.01194668 | G29: 9.6090826 | H29: 0.50779615 | I29: 7523 | J29: 14815
A30: Taboola
A31: mail.yahoo.com | B31: 5.7003995 | C31: 8.0364689 | D31: 161.90898 | E31: 0.016129032 | F31: 0.0021828608 | G31: 2.6114352 | H31: 0.75494634 | I31: 644697 | J31: 853964
A32: zillow.com | B32: 11.54536 | C32: 128.4805 | D32: 376.96177 | E32: 0.014869888 | F32: 0.0020596928 | G32: 5.6053796 | H32: 0.10318723 | I32: 11736 | J32: 113735
A33: finance.yahoo.com | B33: 20.41755 | C33: 38.708933 | D33: 101.30644 | E33: 0.1 | F33: 0.0020154247 | G33: 10.130644 | H33: 0.58460782 | I33: 39257 | J33: 67151
A34: biblegateway.com | B34: 120.23656 | C34: 364.48334 | D34: 434.52489 | E34: 0.10810811 | F34: 0.0025595499 | G34: 46.975664 | H34: 0.35989937 | I34: 14306 | J34: 39750
A35: reuters.com | B35: 90.674308 | C35: 133.53028 | D35: 507.5041 | E35: 0.075 | F35: 0.0023822286 | G35: 38.062808 | H35: 0.80120863 | I35: 11402 | J35: 14231
A36: androidpolice.com | B36: 227.45814 | C36: 337.65669 | D36: 530.79632 | E36: 0.045454545 | F36: 0.009427494 | G36: 24.127105 | H36: 0.7139613 | I36: 7860 | J36: 11009
A37: TripleLift
A38: taboolanews.com | B38: 6.665053 | C38: 19.334503 | D38: 90.738031 | E38: 0.028571429 | F38: 0.0025708829 | G38: 2.5925152 | H38: 0.41780407 | I38: 75089 | J38: 179723
A39: cbsnews.com | B39: 44.795921 | C39: 57.93336 | D39: 48.324765 | E39: 0.27777778 | F39: 0.0033371154 | G39: 13.423546 | H39: 0.81161361 | I39: 104268 | J39: 128470
A40: msn.com | B40: 51.055956 | C40: 90.282491 | D40: 5999.9938 | E40: 0.0033444816 | F40: 0.0025442911 | G40: 20.066869 | H40: 0.76767047 | I40: 66458 | J40: 86571
A41: forbes.com | B41: 64.405999 | C41: 123.31734 | D41: 515.3768 | E41: 0.02972973 | F41: 0.0042034946 | G41: 15.322013 | H41: 0.54779438 | I41: 45972 | J41: 83922
A42: news.yahoo.com | B42: 163.55198 | C42: 325.29386 | D42: 754.3926 | E42: 0.079646018 | F42: 0.0027220389 | G42: 60.084366 | H42: 0.5317707 | I42: 20872 | J42: 39250
A43: yahoo.com | B43: 51.067631 | C43: 140.38508 | D43: 475.27368 | E43: 0.030769231 | F43: 0.0034920891 | G43: 14.623805 | H43: 0.4172418 | I43: 13542 | J43: 32456
...

Sheet PBL_DA_CAPSTONE_DATA
A1: Audience Segment | B1: Category | C1: Sub Category | D1: Creative Size | E1: Creative Messaging | F1: City | G1: State | H1: App/URL | I1: Exchange | J1: Device Make | K1: Impressions | L1: Clicks | M1: Viewable Impressions | N1: Measurable Impressions | O1: Total Conversions | P1: Gross Cost
A2: Arts and Entertainment | B2: Arts and Entertainment | D2: 320x50 | E2: Subscribe Today - 10% Discount | F2: Orlando-Daytona Beach | G2: Florida | H2: nbcchicago.com | I2: Google Ad Manager | J2: Smartphone | K2: 7248 | L2: 10 | M2: 3988 | N2: 6863 | O2: 7 | P2: 1247
A3: Arts and Entertainment | B3: Celebrities and Entertainment News | D3: 320x50 | E3: 10% Discount - Ends 6/1 | F3: Orlando-Daytona Beach | G3: Florida | H3: icy-veins.com | I3: Google Ad Manager | J3: Smartphone | K3: 9261 | L3: 66 | M3: 3852 | N3: 8526 | O3: 9 | P3: 6511.0296
A4: Arts and Entertainment | B4: Comics and Animation | D4: 300x250 | E4: Subscribe Today - 10% Discount | F4: Knoxville | G4: Tennessee | H4: fox59.com | I4: Google Ad Manager | J4: Smartphone | K4: 7583 | L4: 45 | M4: 4608 | N4: 5881 | O4: 1 | P4: 5033.4826
A5: Arts and Entertainment | B5: Events and Listings | C5: Clubs and Nightlife | D5: 300x250 | E5: 10% Discount - Ends 6/1 | F5: Chicago | G5: Illinois | H5: activebeat.com | I5: Magnite DV+ | J5: Windows PC | K5: 81905 | L5: 220 | M5: 61995 | N5: 71110 | O5: 24 | P5: 7065.6693
A6: Arts and Entertainment | B6: Events and Listings | C6: Concerts and Music Festivals | D6: 300x50 | E6: Sign up Today - 10% Off | F6: Chicago | G6: Illinois | H6: usssa.com | I6: Google Ad Manager | J6: Smartphone | K6: 446774 | L6: 951 | M6: 196581 | N6: 379758 | O6: 33 | P6: 6956.6274
A7: Arts and Entertainment | B7: Events and Listings | C7: Event Ticket Sales | D7: 300x50 | E7: Sign up Today - 10% Off | F7: Nashville | G7: Tennessee | H7: wikihow.com | I7: Magnite DV+ | J7: Smartphone | K7: 23488 | L7: 75 | M7: 4620 | N7: 22254 | O7: 9 | P7: 6667.7277
A8: Arts and Entertainment | B8: Events and Listings | C8: Expos and Conventions | D8: 300x250 | E8: Subscribe Today - 10% Discount | F8: Los Angeles | G8: California | H8: zillow.com | I8: Google Ad Manager | J8: Apple PC | K8: 20833 | L8: 87 | M8: 1777 | N8: 17211 | O8: 9 | P8: 5542.5122
A9: Arts and Entertainment | B9: Events and Listings | C9: Film Festivals | D9: 320x50 | E9: Sign up Now - 10% Off | F9: Los Angeles | G9: California | H9: ebay.com | I9: Google Ad Manager | J9: Smartphone | K9: 405957 | L9: 874 | M9: 204189 | N9: 385654 | O9: 16 | P9: 5864.1265
A10: Arts and Entertainment | B10: Events and Listings | C10: Food and Beverage Events | D10: 300x250 | E10: Sign up Today - 10% Off | F10: Los Angeles | G10: California | H10: mail.aol.com | I10: Google Ad Manager | J10: Smartphone | K10: 224359 | L10: 480 | M10: 163149 | N10: 200859 | O10: 5 | P10: 4196.9368
A11: Arts and Entertainment | B11: Events and Listings | C11: Live Sporting Events | D11: 320x50 | E11: Subscribe Today - 10% Discount | F11: Chicago | G11: Illinois | H11: my.yahoo.com | I11: Google Ad Manager | J11: Smartphone | K11: 21028 | L11: 10 | M11: 5781 | N11: 16134 | O11: 11 | P11: 5101.3217
A12: Arts and Entertainment | B12: Movies | D12: 300x250 | E12: 10% Discount - Ends 6/1 | F12: Nashville | G12: Tennessee | H12: funnyand.com | I12: Google Ad Manager | J12: Smartphone | K12: 9273 | L12: 70 | M12: 4648 | N12: 8751 | O12: 5 | P12: 4986.5194
A13: Arts and Entertainment | B13: Music and Audio | D13: 300x250 | E13: Sign up Today - 10% Off | F13: Jacksonville | G13: Florida | H13: chicagotribune.com | I13: Google Ad Manager | J13: Smartphone | K13: 7628 | L13: 19 | M13: 5048 | N13: 7154 | O13: 5 | P13: 6684.0628
A14: Arts and Entertainment | B14: TV and Video | D14: 300x50 | E14: Subscribe Today - 10% Discount | F14: New York City | G14: New York | H14: msn.com | I14: BidSwitch | J14: Smartphone | K14: 13946 | L14: 40 | M14: 3142 | N14: 8823 | O14: 8 | P14: 4920.2346
A15: Automotive | B15: Auto Buyers | C15: Audi Q | D15: 300x250 | E15: Sign up Now - 10% Off | F15: Grand Rapids-Kalamazoo | G15: Michigan | H15: accuweather.com | I15: Xandr - Monetize SSP (AppNexus) | J15: Smartphone | K15: 10501 | L15: 90 | M15: 4126 | N15: 7654 | O15: 8 | P15: 6244.5179
A16: Automotive | B16: Auto Buyers | C16: BMW | D16: 300x250 | E16: Sign up Today - 10% Off | F16: West Palm Beach-Ft. Pierce | G16: Florida | H16: firstcoastnews.com | I16: BidSwitch | J16: Smartphone | K16: 12092 | L16: 30 | M16: 2042 | N16: 10315 | O16: 8 | P16: 6245.1348
A17: Automotive | B17: Auto Buyers | C17: Dodge | D17: 320x50 | E17: Subscribe Today - 10% Discount | F17: Champaign & Springfield-Decatur | G17: Illinois | H17: historycollection.com | I17: Google Ad Manager | J17: Smartphone | K17: 138904 | L17: 399 | M17: 98952 | N17: 120688 | O17: 25 | P17: 5038.6447
A18: Automotive | B18: Auto Buyers | C18: Ford | D18: 300x250 | E18: 10% Discount - Ends 6/1 | F18: Nashville | G18: Tennessee | H18: foxnews.com | I18: BidSwitch | J18: Apple PC | K18: 29323 | L18: 88 | M18: 13822 | N18: 26934 | O18: 9 | P18: 6096.0455
A19: Automotive | B19: Auto Buyers | C19: Honda | D19: 300x250 | E19: Subscribe Today - 10% Discount | F19: Nashville | G19: Tennessee | H19: npr.org | I19: Yahoo Exchange | J19: Smartphone | K19: 8000 | L19: 10 | M19: 4400 | N19: 6379 | O19: 1 | P19: 6159.3669
A20: Automotive | B20: Auto Buyers | C20: Hyundai | D20: 320x50 | E20: 10% Discount - Ends 6/1 | F20: New York City | G20: New York | H20: daily-choices.com | I20: OpenX | J20: Smartphone | K20: 25532 | L20: 140 | M20: 15219 | N20: 21497 | O20: 9 | P20: 6047.1741
A21: Automotive | B21: Auto Buyers | C21: Jeep | D21: 300x250 | E21: Sign up Today - 10% Off | F21: New York City | G21: New York | H21: weather.com | I21: Smart RTB+ (Smartadserver) | J21: Windows PC | K21: 96779 | L21: 299 | M21: 9831 | N21: 63640 | O21: 12 | P21: 6317.5108
A22: Automotive | B22: Auto Buyers | C22: Mazda | D22: 300x250 | E22: 10% Discount - Ends 6/1 | F22: Miami-Ft. Lauderdale | G22: Florida | H22: iflscience.com | I22: Google Ad Manager | J22: Smartphone | K22: 11672 | L22: 84 | M22: 7619 | N22: 9999 | O22: 7 | P22: 5284.277
A23: Automotive | B23: Auto Buyers | C23: Mercedes | D23: 320x50 | E23: Subscribe Today - 10% Discount | F23: Lansing | G23: Michigan | H23: realtor.com | I23: Index Exchange | J23: Smartphone | K23: 42459 | L23: 121 | M23: 15187 | N23: 37408 | O23: 11 | P23: 6321.4917
A24: Automotive | B24: Auto Buyers | C24: Nissan | D24: 320x50 | E24: Subscribe Today - 10% Discount | F24: Miami-Ft. Lauderdale | G24: Florida | H24: britannica.com | I24: Google Ad Manager | J24: Smartphone | K24: 8068 | L24: 10 | M24: 5545 | N24: 7554 | O24: 1 | P24: 5995.041
A25: Automotive | B25: Auto Buyers | C25: Opel | D25: 300x250 | E25: Subscribe Today - 10% Discount | F25: New York City | G25: New York | H25: finance.yahoo.com | I25: Google Ad Manager | J25: Smartphone | K25: 286998 | L25: 815 | M25: 61586 | N25: 247500 | O25: 13 | P25: 6395.5506
A26: Automotive | B26: Auto Buyers | C26: Peugeot | D26: 300x250 | E26: Sign up Today - 10% Off | F26: New York City | G26: New York | H26: usatoday.com | I26: Google Ad Manager | J26: Smartphone | K26: 186404 | L26: 940 | M26: 30885 | N26: 151358 | O26: 3 | P26: 4702.0275
... A34: Automotive | B34: Auto Buyers | C34: Van | D34: 320x50 | E34: Sign up Today - 10% Off | F34: Chicago | G34: Illinois | H34: tasteofhome.com | I34: Google Ad Manager | J34: Smartphone | K34: 9153 | L34: 23 | M34: 4345 | N34: 8376 | O34: 14 | P34: 5007.5258
A35: Automotive | B35: Auto Buyers | D35: 320x50 | E35: Sign up Now - 10% Off | F35: Los Angeles | G35: California | H35: whatismyipaddress.com | I35: Google Ad Manager | J35: Smartphone | K35: 42830 | L35: 160 | M35: 24499 | N35: 34496 | O35: 5 | P35: 6261.5757
A36: Automotive | B36: Auto Buyers | C36: Crossover | D36: 320x50 | E36: Sign up Now - 10% Off | F36: Chicago | G36: Illinois | H36: usatoday.com | I36: Google Ad Manager | J36: Smartphone | K36: 25539 | L36: 78 | M36: 12130 | N36: 24129 | O36: 15 | P36: 4804.4932
A37: Automotive | B37: Auto Buyers | C37: Luxury | D37: 320x50 | E37: Sign up Now - 10% Off | F37: Los Angeles | G37: California | H37: al.com | I37: PubMatic | J37: Smartphone | K37: 14489 | L37: 37 | M37: 12453 | N37: 13873 | O37: 10 | P37: 6195.8407
A38: Automotive | B38: Auto Buyers | C38: SUV | D38: 300x250 | E38: Sign up Today - 10% Off | F38: New York City | G38: New York | H38: homeaddict.io | I38: BidSwitch | J38: Windows PC | K38: 99205 | L38: 230 | M38: 49240 | N38: 72687 | O38: 21 | P38: 6185.0025
A39: Automotive | B39: Auto Buyers | C39: Sedan | D39: 300x250 | E39: Sign up Today - 10% Off | F39: Chicago | G39: Illinois | H39: mail.aol.com | I39: Index Exchange | J39: Windows PC | K39: 25889 | L39: 110 | M39: 18382 | N39: 23328 | O39: 15 | P39: 4977.7848
A40: Automotive | B40: Auto Buyers | C40: Truck | D40: 300x250 | E40: Sign up Now - 10% Off | F40: Tampa-St Petersburg (Sarasota) | G40: Florida | H40: msn.com | I40: BidSwitch | J40: Smartphone | K40: 12974 | L40: 84 | M40: 7521 | N40: 10959 | O40: 7 | P40: 6301.8688
A41: Automotive | B41: Auto Car Purchase Next Year | C41: Yes | D41: 320x50 | E41: Subscribe Today - 10% Discount | F41: Grand Rapids-Kalamazoo | G41: Michigan | H41: whatismyipaddress.com | I41: Index Exchange | J41: Smartphone | K41: 31359 | L41: 66 | M41: 18348 | N41: 25950 | O41: 24 | P41: 1623.6148
A42: Automotive | B42: Auto Loyalists and Defectors | C42: Auto Make Defectors | D42: 320x50 | E42: Subscribe Today - 10% Discount | F42: Los Angeles | G42: California | H42: si.com | I42: TripleLift | J42: Smartphone | K42: 11561 | L42: 87 | M42: 4063 | N42: 9941 | O42: 5 | P42: 1911.932
A43: Automotive | B43: Boats and Watercraft | D43: 320x50 | E43: Subscribe Today - 10% Discount | F43: Chicago | G43: Illinois | H43: fandomwire.com | I43: OpenX | J43: Smartphone | K43: 111624 | L43: 590 | M43: 40343 | N43: 101306 | O43: 21 | P43: 6510.4467
A44: Automotive | B44: Brands | C44: Acura | D44: 300x250 | E44: Subscribe Today - 10% Discount | F44: New York City | G44: New York | H44: mail.aol.com | I44: Google Ad Manager | J44: Windows PC | K44: 83854 | L44: 197 | M44: 60626 | N44: 76071 | O44: 15 | P44: 5783.8438
A45: Automotive | B45: Brands | C45: Aston Martin | D45: 300x250 | E45: Subscribe Today - 10% Discount | F45: Orlando-Daytona Beach | G45: Florida | H45: yahoo.com | I45: Google Ad Manager | J45: Windows PC | K45: 84460 | L45: 209 | M45: 13169 | N45: 26688 | O45: 1 | P45: 4279.231
A46: Automotive | B46: Brands | C46: BMW | D46: 300x50 | E46: Sign up Now - 10% Off | F46: West Palm Beach-Ft. Pierce | G46: Florida | H46: forbes.com | I46: TripleLift | J46: Smartphone | K46: 88022 | L46: 370 | M46: 45972 | N46: 83922 | O46: 11 | P46: 5669.1448
A47: Automotive | B47: Brands | C47: Bugatti | D47: 320x50 | E47: Sign up Today - 10% Off | F47: Jacksonville | G47: Florida | H47: mobileposse.com | I47: Google Ad Manager | J47: Smartphone | K47: 98509 | L47: 299 | M47: 30688 | N47: 109518 | O47: 15 | P47: 2059.2703
...
